2022-07-15 15:57:09,519 INFO    MainThread:62344 [internal.py:wandb_internal():93] W&B internal server running at pid: 62344, started at: 2022-07-15 15:57:09.519422
2022-07-15 15:57:09,520 INFO    WriterThread:62344 [datastore.py:open_for_write():75] open: /Users/jonnycook/Desktop/MARLGen/epymarl/src/wandb/run-20220715_155708-16bumaap/run-16bumaap.wandb
2022-07-15 15:57:09,521 DEBUG   SenderThread:62344 [sender.py:send():236] send: header
2022-07-15 15:57:09,522 DEBUG   SenderThread:62344 [sender.py:send():236] send: run
2022-07-15 15:57:25,685 WARNING MainThread:62344 [internal.py:wandb_internal():153] Internal process interrupt: 1
2022-07-15 15:57:26,758 ERROR   SenderThread:62344 [internal_api.py:execute():161] 409 response executing GraphQL.
2022-07-15 15:57:26,758 ERROR   SenderThread:62344 [internal_api.py:execute():162] {"errors":[{"message":"Error 1062: Duplicate entry '1017065-16bumaap' for key 'PRIMARY'","path":["upsertBucket"]}],"data":{"upsertBucket":null}}
2022-07-15 15:57:27,584 INFO    WriterThread:62344 [datastore.py:close():279] close: /Users/jonnycook/Desktop/MARLGen/epymarl/src/wandb/run-20220715_155708-16bumaap/run-16bumaap.wandb
2022-07-15 15:57:27,585 INFO    HandlerThread:62344 [handler.py:finish():806] shutting down handler
2022-07-15 15:57:27,696 ERROR   MainThread:62344 [internal.py:wandb_internal():165] Thread SenderThread:
Traceback (most recent call last):
  File "/Users/jonnycook/opt/anaconda3/envs/MARLGen/lib/python3.7/site-packages/wandb/apis/normalize.py", line 25, in wrapper
    return func(*args, **kwargs)
  File "/Users/jonnycook/opt/anaconda3/envs/MARLGen/lib/python3.7/site-packages/wandb/sdk/internal/internal_api.py", line 1341, in upsert_run
    response = self.gql(mutation, variable_values=variable_values, **kwargs)
  File "/Users/jonnycook/opt/anaconda3/envs/MARLGen/lib/python3.7/site-packages/wandb/sdk/lib/retry.py", line 108, in __call__
    result = self._call_fn(*args, **kwargs)
  File "/Users/jonnycook/opt/anaconda3/envs/MARLGen/lib/python3.7/site-packages/wandb/sdk/internal/internal_api.py", line 158, in execute
    return self.client.execute(*args, **kwargs)
  File "/Users/jonnycook/opt/anaconda3/envs/MARLGen/lib/python3.7/site-packages/wandb/vendor/gql-0.2.0/wandb_gql/client.py", line 52, in execute
    result = self._get_result(document, *args, **kwargs)
  File "/Users/jonnycook/opt/anaconda3/envs/MARLGen/lib/python3.7/site-packages/wandb/vendor/gql-0.2.0/wandb_gql/client.py", line 60, in _get_result
    return self.transport.execute(document, *args, **kwargs)
  File "/Users/jonnycook/opt/anaconda3/envs/MARLGen/lib/python3.7/site-packages/wandb/vendor/gql-0.2.0/wandb_gql/transport/requests.py", line 39, in execute
    request.raise_for_status()
  File "/Users/jonnycook/opt/anaconda3/envs/MARLGen/lib/python3.7/site-packages/requests/models.py", line 960, in raise_for_status
    raise HTTPError(http_error_msg, response=self)
requests.exceptions.HTTPError: 409 Client Error: Conflict for url: https://api.wandb.ai/graphql

During handling of the above exception, another exception occurred:

Traceback (most recent call last):
  File "/Users/jonnycook/opt/anaconda3/envs/MARLGen/lib/python3.7/site-packages/wandb/sdk/internal/internal_util.py", line 51, in run
    self._run()
  File "/Users/jonnycook/opt/anaconda3/envs/MARLGen/lib/python3.7/site-packages/wandb/sdk/internal/internal_util.py", line 102, in _run
    self._process(record)
  File "/Users/jonnycook/opt/anaconda3/envs/MARLGen/lib/python3.7/site-packages/wandb/sdk/internal/internal.py", line 310, in _process
    self._sm.send(record)
  File "/Users/jonnycook/opt/anaconda3/envs/MARLGen/lib/python3.7/site-packages/wandb/sdk/internal/sender.py", line 238, in send
    send_handler(record)
  File "/Users/jonnycook/opt/anaconda3/envs/MARLGen/lib/python3.7/site-packages/wandb/sdk/internal/sender.py", line 696, in send_run
    self._init_run(run, config_value_dict)
  File "/Users/jonnycook/opt/anaconda3/envs/MARLGen/lib/python3.7/site-packages/wandb/sdk/internal/sender.py", line 734, in _init_run
    commit=run.git.last_commit or None,
  File "/Users/jonnycook/opt/anaconda3/envs/MARLGen/lib/python3.7/site-packages/wandb/apis/normalize.py", line 27, in wrapper
    raise CommError(err.response, err)
wandb.errors.CommError: <Response [409]>
2022-07-15 15:57:29,735 INFO    MainThread:62344 [internal.py:handle_exit():80] Internal process exited
