{
  "artifacts": [],
  "command": "my_main",
  "experiment": {
    "base_dir": "/Users/jonnycook/Desktop/MARLGen/epymarl/src",
    "dependencies": [
      "munch==2.5.0",
      "numpy==1.21.5",
      "PyYAML==6.0",
      "sacred==0.8.2",
      "torch==1.10.2",
      "wandb==0.12.21"
    ],
    "mainfile": "main.py",
    "name": "pymarl",
    "repositories": [],
    "sources": [
      [
        "main.py",
        "_sources/main_55c0e4c54e7c34c7f0ae305988eda277.py"
      ],
      [
        "run.py",
        "_sources/run_5cb8997a55c355c5821818b0d695f0d4.py"
      ],
      [
        "utils/logging.py",
        "_sources/logging_8309e899ab76a4e610428ba7ee8d8acb.py"
      ]
    ]
  },
  "fail_trace": [
    "Traceback (most recent call last):\n",
    "  File \"/Users/jonnycook/opt/anaconda3/envs/MARLGen/lib/python3.7/site-packages/wandb/sdk/wandb_run.py\", line 1871, in _atexit_cleanup\n    self._on_finish()\n",
    "  File \"/Users/jonnycook/opt/anaconda3/envs/MARLGen/lib/python3.7/site-packages/wandb/sdk/wandb_run.py\", line 1972, in _on_finish\n    self._console_stop()  # TODO: there's a race here with jupyter console logging\n",
    "  File \"/Users/jonnycook/opt/anaconda3/envs/MARLGen/lib/python3.7/site-packages/wandb/sdk/wandb_run.py\", line 1911, in _console_stop\n    self._restore()\n",
    "  File \"/Users/jonnycook/opt/anaconda3/envs/MARLGen/lib/python3.7/site-packages/wandb/sdk/wandb_run.py\", line 1838, in _restore\n    self._out_redir.uninstall()\n",
    "  File \"/Users/jonnycook/opt/anaconda3/envs/MARLGen/lib/python3.7/site-packages/wandb/sdk/lib/redirect.py\", line 726, in uninstall\n    time.sleep(1)\n",
    "KeyboardInterrupt\n",
    "\nDuring handling of the above exception, another exception occurred:\n\n",
    "Traceback (most recent call last):\n",
    "  File \"/Users/jonnycook/opt/anaconda3/envs/MARLGen/lib/python3.7/site-packages/wandb/sdk/wandb_init.py\", line 1043, in init\n    run = wi.init()\n",
    "  File \"/Users/jonnycook/opt/anaconda3/envs/MARLGen/lib/python3.7/site-packages/wandb/sdk/wandb_init.py\", line 527, in init\n    self._wl._global_run_stack[-1].finish()\n",
    "  File \"/Users/jonnycook/opt/anaconda3/envs/MARLGen/lib/python3.7/site-packages/wandb/sdk/wandb_run.py\", line 256, in wrapper\n    return func(self, *args, **kwargs)\n",
    "  File \"/Users/jonnycook/opt/anaconda3/envs/MARLGen/lib/python3.7/site-packages/wandb/sdk/wandb_run.py\", line 222, in wrapper\n    return func(self, *args, **kwargs)\n",
    "  File \"/Users/jonnycook/opt/anaconda3/envs/MARLGen/lib/python3.7/site-packages/wandb/sdk/wandb_run.py\", line 1673, in finish\n    return self._finish(exit_code, quiet)\n",
    "  File \"/Users/jonnycook/opt/anaconda3/envs/MARLGen/lib/python3.7/site-packages/wandb/sdk/wandb_run.py\", line 1686, in _finish\n    self._atexit_cleanup(exit_code=exit_code)\n",
    "  File \"/Users/jonnycook/opt/anaconda3/envs/MARLGen/lib/python3.7/site-packages/wandb/sdk/wandb_run.py\", line 1875, in _atexit_cleanup\n    wandb.termerror(\"Control-C detected -- Run data was not synced\")\n",
    "  File \"/Users/jonnycook/opt/anaconda3/envs/MARLGen/lib/python3.7/site-packages/wandb/errors/term.py\", line 67, in termerror\n    **kwargs,\n",
    "  File \"/Users/jonnycook/opt/anaconda3/envs/MARLGen/lib/python3.7/site-packages/wandb/errors/term.py\", line 96, in _log\n    click.echo(line, file=sys.stderr, nl=newline)\n",
    "  File \"/Users/jonnycook/opt/anaconda3/envs/MARLGen/lib/python3.7/site-packages/click/utils.py\", line 298, in echo\n    file.write(out)  # type: ignore\n",
    "BrokenPipeError: [Errno 32] Broken pipe\n",
    "\nDuring handling of the above exception, another exception occurred:\n\n",
    "Traceback (most recent call last):\n",
    "  File \"/Users/jonnycook/opt/anaconda3/envs/MARLGen/lib/python3.7/site-packages/wandb/sdk/wandb_init.py\", line 1051, in init\n    getcaller()\n",
    "  File \"/Users/jonnycook/opt/anaconda3/envs/MARLGen/lib/python3.7/site-packages/wandb/sdk/wandb_init.py\", line 740, in getcaller\n    print(\"Problem at:\", src, line, func)\n",
    "BrokenPipeError: [Errno 32] Broken pipe\n",
    "\nDuring handling of the above exception, another exception occurred:\n\n",
    "Traceback (most recent call last):\n",
    "  File \"/Users/jonnycook/opt/anaconda3/envs/MARLGen/lib/python3.7/site-packages/wandb/sdk/wandb_init.py\", line 1068, in init\n    traceback.print_exc()\n",
    "  File \"/Users/jonnycook/opt/anaconda3/envs/MARLGen/lib/python3.7/traceback.py\", line 163, in print_exc\n    print_exception(*sys.exc_info(), limit=limit, file=file, chain=chain)\n",
    "  File \"/Users/jonnycook/opt/anaconda3/envs/MARLGen/lib/python3.7/traceback.py\", line 105, in print_exception\n    print(line, file=file, end=\"\")\n",
    "BrokenPipeError: [Errno 32] Broken pipe\n",
    "\nDuring handling of the above exception, another exception occurred:\n\n",
    "Traceback (most recent call last):\n",
    "  File \"/Users/jonnycook/opt/anaconda3/envs/MARLGen/lib/python3.7/site-packages/sacred/config/captured_function.py\", line 42, in captured_function\n    result = wrapped(*args, **kwargs)\n",
    "  File \"/Users/jonnycook/Desktop/MARLGen/epymarl/src/main.py\", line 35, in my_main\n    wandb.init(project='marlgen', entity='jonnycook', name=logging_name, reinit=True)\n",
    "  File \"/Users/jonnycook/opt/anaconda3/envs/MARLGen/lib/python3.7/site-packages/wandb/sdk/wandb_init.py\", line 1078, in init\n    wandb.termerror(\"Abnormal program exit\")\n",
    "  File \"/Users/jonnycook/opt/anaconda3/envs/MARLGen/lib/python3.7/site-packages/wandb/errors/term.py\", line 67, in termerror\n    **kwargs,\n",
    "  File \"/Users/jonnycook/opt/anaconda3/envs/MARLGen/lib/python3.7/site-packages/wandb/errors/term.py\", line 96, in _log\n    click.echo(line, file=sys.stderr, nl=newline)\n",
    "  File \"/Users/jonnycook/opt/anaconda3/envs/MARLGen/lib/python3.7/site-packages/click/utils.py\", line 298, in echo\n    file.write(out)  # type: ignore\n",
    "BrokenPipeError: [Errno 32] Broken pipe\n"
  ],
  "heartbeat": "2022-07-16T16:24:44.833056",
  "host": {
    "ENV": {},
    "cpu": "Apple M1",
    "hostname": "Jonnys-MBP",
    "os": [
      "Darwin",
      "Darwin-20.5.0-x86_64-i386-64bit"
    ],
    "python_version": "3.7.11"
  },
  "meta": {
    "command": "my_main",
    "options": {
      "--beat-interval": null,
      "--capture": null,
      "--comment": null,
      "--debug": false,
      "--enforce_clean": false,
      "--file_storage": null,
      "--force": false,
      "--help": false,
      "--loglevel": null,
      "--mongo_db": null,
      "--name": null,
      "--pdb": false,
      "--print-config": false,
      "--priority": null,
      "--queue": false,
      "--s3": null,
      "--sql": null,
      "--tiny_db": null,
      "--unobserved": false,
      "COMMAND": null,
      "UPDATE": [],
      "help": false,
      "with": false
    }
  },
  "resources": [],
  "result": null,
  "start_time": "2022-07-16T16:24:44.607647",
  "status": "FAILED",
  "stop_time": "2022-07-16T16:24:44.834324"
}