2022-07-09 08:21:30,208 INFO    MainThread:1277 [internal.py:wandb_internal():93] W&B internal server running at pid: 1277, started at: 2022-07-09 08:21:30.208257
2022-07-09 08:21:30,209 INFO    WriterThread:1277 [datastore.py:open_for_write():75] open: /Users/jonnycook/Desktop/MARLGen/epymarl/wandb/run-20220709_082129-pjf8ga10/run-pjf8ga10.wandb
2022-07-09 08:21:30,211 DEBUG   SenderThread:1277 [sender.py:send():235] send: header
2022-07-09 08:21:30,211 DEBUG   SenderThread:1277 [sender.py:send():235] send: run
2022-07-09 08:21:33,910 ERROR   SenderThread:1277 [retry.py:__call__():126] Retry attempt failed:
Traceback (most recent call last):
  File "/Users/jonnycook/opt/anaconda3/envs/MARLGen/lib/python3.7/site-packages/urllib3/connectionpool.py", line 710, in urlopen
    chunked=chunked,
  File "/Users/jonnycook/opt/anaconda3/envs/MARLGen/lib/python3.7/site-packages/urllib3/connectionpool.py", line 386, in _make_request
    self._validate_conn(conn)
  File "/Users/jonnycook/opt/anaconda3/envs/MARLGen/lib/python3.7/site-packages/urllib3/connectionpool.py", line 1040, in _validate_conn
    conn.connect()
  File "/Users/jonnycook/opt/anaconda3/envs/MARLGen/lib/python3.7/site-packages/urllib3/connection.py", line 426, in connect
    tls_in_tls=tls_in_tls,
  File "/Users/jonnycook/opt/anaconda3/envs/MARLGen/lib/python3.7/site-packages/urllib3/util/ssl_.py", line 450, in ssl_wrap_socket
    sock, context, tls_in_tls, server_hostname=server_hostname
  File "/Users/jonnycook/opt/anaconda3/envs/MARLGen/lib/python3.7/site-packages/urllib3/util/ssl_.py", line 493, in _ssl_wrap_socket_impl
    return ssl_context.wrap_socket(sock, server_hostname=server_hostname)
  File "/Users/jonnycook/opt/anaconda3/envs/MARLGen/lib/python3.7/ssl.py", line 423, in wrap_socket
    session=session
  File "/Users/jonnycook/opt/anaconda3/envs/MARLGen/lib/python3.7/ssl.py", line 870, in _create
    self.do_handshake()
  File "/Users/jonnycook/opt/anaconda3/envs/MARLGen/lib/python3.7/ssl.py", line 1139, in do_handshake
    self._sslobj.do_handshake()
ssl.SSLCertVerificationError: [SSL: CERTIFICATE_VERIFY_FAILED] certificate verify failed: self signed certificate (_ssl.c:1091)

During handling of the above exception, another exception occurred:

Traceback (most recent call last):
  File "/Users/jonnycook/opt/anaconda3/envs/MARLGen/lib/python3.7/site-packages/requests/adapters.py", line 450, in send
    timeout=timeout
  File "/Users/jonnycook/opt/anaconda3/envs/MARLGen/lib/python3.7/site-packages/urllib3/connectionpool.py", line 786, in urlopen
    method, url, error=e, _pool=self, _stacktrace=sys.exc_info()[2]
  File "/Users/jonnycook/opt/anaconda3/envs/MARLGen/lib/python3.7/site-packages/urllib3/util/retry.py", line 592, in increment
    raise MaxRetryError(_pool, url, error or ResponseError(cause))
urllib3.exceptions.MaxRetryError: HTTPSConnectionPool(host='api.wandb.ai', port=443): Max retries exceeded with url: /graphql (Caused by SSLError(SSLCertVerificationError(1, '[SSL: CERTIFICATE_VERIFY_FAILED] certificate verify failed: self signed certificate (_ssl.c:1091)')))

During handling of the above exception, another exception occurred:

Traceback (most recent call last):
  File "/Users/jonnycook/opt/anaconda3/envs/MARLGen/lib/python3.7/site-packages/wandb/sdk/lib/retry.py", line 102, in __call__
    result = self._call_fn(*args, **kwargs)
  File "/Users/jonnycook/opt/anaconda3/envs/MARLGen/lib/python3.7/site-packages/wandb/sdk/internal/internal_api.py", line 140, in execute
    return self.client.execute(*args, **kwargs)
  File "/Users/jonnycook/opt/anaconda3/envs/MARLGen/lib/python3.7/site-packages/wandb/vendor/gql-0.2.0/wandb_gql/client.py", line 52, in execute
    result = self._get_result(document, *args, **kwargs)
  File "/Users/jonnycook/opt/anaconda3/envs/MARLGen/lib/python3.7/site-packages/wandb/vendor/gql-0.2.0/wandb_gql/client.py", line 60, in _get_result
    return self.transport.execute(document, *args, **kwargs)
  File "/Users/jonnycook/opt/anaconda3/envs/MARLGen/lib/python3.7/site-packages/wandb/vendor/gql-0.2.0/wandb_gql/transport/requests.py", line 38, in execute
    request = requests.post(self.url, **post_args)
  File "/Users/jonnycook/opt/anaconda3/envs/MARLGen/lib/python3.7/site-packages/requests/api.py", line 117, in post
    return request('post', url, data=data, json=json, **kwargs)
  File "/Users/jonnycook/opt/anaconda3/envs/MARLGen/lib/python3.7/site-packages/requests/api.py", line 61, in request
    return session.request(method=method, url=url, **kwargs)
  File "/Users/jonnycook/opt/anaconda3/envs/MARLGen/lib/python3.7/site-packages/requests/sessions.py", line 529, in request
    resp = self.send(prep, **send_kwargs)
  File "/Users/jonnycook/opt/anaconda3/envs/MARLGen/lib/python3.7/site-packages/requests/sessions.py", line 645, in send
    r = adapter.send(request, **kwargs)
  File "/Users/jonnycook/opt/anaconda3/envs/MARLGen/lib/python3.7/site-packages/requests/adapters.py", line 517, in send
    raise SSLError(e, request=request)
requests.exceptions.SSLError: HTTPSConnectionPool(host='api.wandb.ai', port=443): Max retries exceeded with url: /graphql (Caused by SSLError(SSLCertVerificationError(1, '[SSL: CERTIFICATE_VERIFY_FAILED] certificate verify failed: self signed certificate (_ssl.c:1091)')))
2022-07-09 08:21:59,735 DEBUG   HandlerThread:1277 [handler.py:handle_request():141] handle_request: shutdown
2022-07-09 08:21:59,736 INFO    HandlerThread:1277 [handler.py:finish():806] shutting down handler
2022-07-09 08:22:00,329 INFO    WriterThread:1277 [datastore.py:close():279] close: /Users/jonnycook/Desktop/MARLGen/epymarl/wandb/run-20220709_082129-pjf8ga10/run-pjf8ga10.wandb
2022-07-09 08:22:04,699 INFO    SenderThread:1277 [dir_watcher.py:__init__():205] watching files in: /Users/jonnycook/Desktop/MARLGen/epymarl/wandb/run-20220709_082129-pjf8ga10/files
2022-07-09 08:22:04,699 INFO    SenderThread:1277 [sender.py:_start_run_threads():815] run started: pjf8ga10 with start time 1657351289
2022-07-09 08:22:04,699 INFO    SenderThread:1277 [sender.py:finish():1111] shutting down sender
2022-07-09 08:22:04,699 INFO    SenderThread:1277 [dir_watcher.py:finish():336] shutting down directory watcher
2022-07-09 08:22:05,705 INFO    SenderThread:1277 [dir_watcher.py:finish():366] scan: /Users/jonnycook/Desktop/MARLGen/epymarl/wandb/run-20220709_082129-pjf8ga10/files
2022-07-09 08:22:05,705 INFO    SenderThread:1277 [dir_watcher.py:finish():380] scan save: /Users/jonnycook/Desktop/MARLGen/epymarl/wandb/run-20220709_082129-pjf8ga10/files/config.yaml config.yaml
2022-07-09 08:22:05,706 INFO    SenderThread:1277 [file_pusher.py:finish():145] shutting down file pusher
2022-07-09 08:22:05,706 INFO    SenderThread:1277 [file_pusher.py:join():150] waiting for file pusher
2022-07-09 08:22:06,539 INFO    Thread-9  :1277 [upload_job.py:push():132] Uploaded file /Users/jonnycook/Desktop/MARLGen/epymarl/wandb/run-20220709_082129-pjf8ga10/files/config.yaml
2022-07-09 08:22:07,556 INFO    MainThread:1277 [internal.py:handle_exit():80] Internal process exited
